Workbook

Sheet monsters original
A1: name | B1: category | C1: cr | D1: size | E1: type | F1: descriptive_tags | G1: alignment | H1: ac | I1: initiative | J1: hp | K1: hp_number | L1: speed | M1: speed_base_number | N1: str | O1: dex | P1: con | Q1: int | R1: wis | S1: cha | T1: str_save | U1: dex_save | V1: con_save | W1: int_save | X1: wis_save | Y1: cha_save | Z1: skills | AA1: resistances | AB1: vulnerabilities | AC1: immunities | AD1: gear | AE1: senses | AF1: languages | AG1: full_text
A2: Aboleth | B2: Aboleth | C2: 10 | D2: Large | E2: Aberration | F2: NA | G2: Lawful Evil | H2: 17 | I2: 7 | J2: 150 (20d10 + 40) | K2: 150 | L2: Speed 10 ft., Swim 40 ft. | M2: 10 | N2: 21 | O2: 9 | P2: 15 | Q2: 18 | R2: 15 | S2: 18 | T2: 5 | U2: 3 | V2: 6 | W2: 8 | X2: 6 | Y2: 4 | Z2: History +12, Perception +10 | AA2: NA | AB2: NA | AC2: NA | AD2: NA | AE2: Darkvision 120 ft.; Passive Perception 20 | AF2: Deep Speech; telepathy 120 ft. | AG2: Aboleth Large Aberration, Lawful Evil AC 17 Initiative +7 (17) HP 150 (20d10 + 40) Speed 10 ft., Swim 40 ft. MOD SAVE MOD SAVE MOD SAVE Str 21 +5 +5 Dex 9 âˆ’1 +3 Con 15 +2 +6 Int 18 +4 +8 Wis 15 +2 +6 Cha 18 +4 +4 Skills History +12, Perception +10 Senses Darkvision 120 ft.; Passive Perception 20 Languages Deep Speech; telepathy 120 ft. CR 10 (XP 5,900, or 7,200 in lair; PB +4) Traits Amphibious. The aboleth can breathe air and water. Eldritch Restoration. If destroyed, the aboleth gains a new body in 5d10 days, reviving with all its Hit Points in the Far Realm or another location chosen by the GM. Legendary Resistance (3/Day, or 4/Day in Lair). If the aboleth fails a saving throw, it can choose to suc- ceed instead. Mucus Cloud. While underwater, the aboleth is sur- rounded by mucus. Constitution Saving Throw: DC 14, each creature in a 5-foot Emanation originating from the aboleth at the end of the abolethâ€™s turn. Failure: The target is cursed. Until the curse ends, the targetâ€™s skin becomes slimy, the target can breathe air and water, and it canâ€™t regain Hit Points unless it is underwater. While the cursed creature is outside a body of water, the creature takes 6 (1d12) Acid damage at the end of every 10 minutes unless moisture is applied to its skin before those minutes have passed. Probing Telepathy. If a creature the aboleth can see communicates telepathically with the aboleth, the abo- leth learns the creatureâ€™s greatest desires. Actions Multiattack. The aboleth makes two Tentacle attacks and uses either Consume Memories or Dominate Mind if available. Tentacle. Melee Attack Roll: +9, reach 15 ft. Hit: 12 (2d6 + 5) Bludgeoning damage. If the target is a Large or smaller creature, it has the Grappled condition (es- cape DC 14) from one of four tentacles. Consume Memories. Intelligence Saving Throw: DC 16, one creature within 30 feet that is Charmed or Grap- pled by the aboleth. Failure: 10 (3d6) Psychic damage. Success: Half damage. Failure or Success: The aboleth gains the targetâ€™s memories if the target is a Humanoid and is reduced to 0 Hit Points by this action. Dominate Mind (2/Day). Wisdom Saving Throw: DC 16, one creature the aboleth can see within 30 feet. Failure: The target has the Charmed condition until the aboleth dies or is on a different plane of existence from the target. While Charmed, the target acts as an ally to the aboleth and is under its control while within 60 feet of it. In addition, the aboleth and the target can communicate telepathically with each other over any distance. The target repeats the save whenever it takes damage as well as after every 24 hours it spends at least 1 mile away from the aboleth, ending the effect on itself on a success. Legendary Actions Legendary Action Uses: 3 (4 in Lair). Immediately after another creatureâ€™s turn, the aboleth can expend a use to take one of the following actions. The aboleth regains all expended uses at the start of each of its turns. Lash. The aboleth makes one Tentacle attack. Psychic Drain. If the aboleth has at least one creature Charmed or Grappled, it uses Consume Memories and regains 5 (1d10) Hit Points.
A3: Air Elemental | B3: Air Elemental | C3: 5 | D3: Large | E3: Elemental | F3: NA | G3: Neutral | H3: 15 | I3: 5 | J3: 90 (12d10 + 24) | K3: 90 | L3: Speed 10 ft., Fly 90 ft. (hover) | M3: 10 | N3: 14 | O3: 20 | P3: 14 | Q3: 6 | R3: 10 | S3: 6 | T3: 2 | U3: 5 | V3: 2 | W3: -2 | X3: 0 | Y3: -2 | Z3: NA | AA3: Bludgeoning, Lightning, Piercing, Slashing | AB3: NA | AC3: Poison, Thunder; Exhaustion, Grappled, Paralyzed, Petrified, Poisoned, Prone, Restrained, Unconscious | AD3: NA | AE3: Darkvision 60 ft.; Passive Perception 10 | AF3: Primordial (Auran) | AG3: Air Elemental Large Elemental, Neutral AC 15 Initiative +5 (15) HP 90 (12d10 + 24) Speed 10 ft., Fly 90 ft. (hover) MOD SAVE MOD SAVE MOD SAVE Str 14 +2 +2 Dex 20 +5 +5 Con 14 +2 +2 Int 6 âˆ’2 âˆ’2 Wis 10 +0 +0 Cha 6 âˆ’2 âˆ’2 Resistances Bludgeoning, Lightning, Piercing, Slashing Immunities Poison, Thunder; Exhaustion, Grappled, Paralyzed, Petrified, Poisoned, Prone, Restrained, Unconscious Senses Darkvision 60 ft.; Passive Perception 10 Languages Primordial (Auran) CR 5 (XP 1,800; PB +3) Traits Air Form. The elemental can enter a creatureâ€™s space and stop there. It can move through a space as narrow as 1 inch without expending extra movement to do so. Actions Multiattack. The elemental makes two Thunderous Slam attacks. Thunderous Slam. Melee Attack Roll: +8, reach 10 ft. Hit: 14 (2d8 + 5) Thunder damage. Whirlwind (Recharge 4â€“6). Strength Saving Throw: DC 13, one Medium or smaller creature in the elementalâ€™s space. Failure: 24 (4d10 + 2) Thunder damage, and the target is pushed up to 20 feet straight away from the elemental and has the Prone condition. Success: Half damage only.
A4: Animated Armor | B4: Animated Objects | C4: 1 | D4: Medium | E4: Construct | F4: NA | G4: Unaligned | H4: 18 | I4: 2 | J4: 33 (6d8 + 6) | K4: 33 | L4: Speed 25 ft. | M4: 25 | N4: 14 | O4: 11 | P4: 13 | Q4: 1 | R4: 3 | S4: 1 | T4: 2 | U4: 0 | V4: 1 | W4: -5 | X4: -4 | Y4: -5 | Z4: NA | AA4: NA | AB4: NA | AC4: Poison, Psychic; Charmed, Deafened, Exhaustion, Frightened, Paralyzed, Petrified, Poisoned | AD4: NA | AE4: Blindsight 60 ft.; Passive Perception 6 | AF4: None | AG4: Animated Armor Medium Construct, Unaligned AC 18 Initiative +2 (12) HP 33 (6d8 + 6) Speed 25 ft. MOD SAVE MOD SAVE MOD SAVE Str 14 +2 +2 Dex 11 +0 +0 Con 13 +1 +1 Int 1 âˆ’5 âˆ’5 Wis 3 âˆ’4 âˆ’4 Cha 1 âˆ’5 âˆ’5 Immunities Poison, Psychic; Charmed, Deafened, Exhaustion, Frightened, Paralyzed, Petrified, Poisoned Senses Blindsight 60 ft.; Passive Perception 6 Languages None CR 1 (XP 200; PB +2) Actions Multiattack. The armor makes two Slam attacks. Slam. Melee Attack Roll: +4, reach 5 ft. Hit: 5 (1d6 + 2) Bludgeoning damage.
A5: Animated Flying Sword | B5: Animated Objects | C5: 0.25 | D5: Small | E5: Construct | F5: NA | G5: Unaligned | H5: 17 | I5: 4 | J5: 14 (4d6) | K5: 14 | L5: Speed 5 ft., Fly 50 ft. (hover) | M5: 5 | N5: 12 | O5: 15 | P5: 11 | Q5: 1 | R5: 5 | S5: 1 | T5: 1 | U5: 4 | V5: 0 | W5: -5 | X5: -3 | Y5: -5 | Z5: NA | AA5: NA | AB5: NA | AC5: Poison, Psychic; Charmed, Deafened, Exhaustion, Frightened, Paralyzed, Petrified, Poisoned | AD5: NA | AE5: Blindsight 60 ft.; Passive Perception 7 | AF5: None | AG5: Animated Flying Sword Small Construct, Unaligned AC 17 Initiative +4 (14) HP 14 (4d6) Speed 5 ft., Fly 50 ft. (hover) MOD SAVE MOD SAVE MOD SAVE Str 12 +1 +1 Dex 15 +2 +4 Con 11 +0 +0 Int 1 âˆ’5 âˆ’5 Wis 5 âˆ’3 âˆ’3 Cha 1 âˆ’5 âˆ’5 Immunities Poison, Psychic; Charmed, Deafened, Exhaustion, Frightened, Paralyzed, Petrified, Poisoned Senses Blindsight 60 ft.; Passive Perception 7 Languages None CR 1/4 (XP 50; PB +2) Actions Slash. Melee Attack Roll: +4, reach 5 ft. Hit: 6 (1d8 + 2) Slashing damage.
A6: Animated Rug of Smothering | B6: Animated Objects | C6: 2 | D6: Large | E6: Construct | F6: NA | G6: Unaligned | H6: 12 | I6: 4 | J6: 27 (5d10) | K6: 27 | L6: Speed 10 ft. | M6: 10 | N6: 17 | O6: 14 | P6: 10 | Q6: 1 | R6: 3 | S6: 1 | T6: 3 | U6: 2 | V6: 0 | W6: -5 | X6: -4 | Y6: -5 | Z6: NA | AA6: NA | AB6: NA | AC6: Poison, Psychic; Charmed, Deafened, Exhaustion, Frightened, Paralyzed, Petrified, Poisoned | AD6: NA | AE6: Blindsight 60 ft.; Passive Perception 6 | AF6: None | AG6: Animated Rug of Smothering Large Construct, Unaligned AC 12 Initiative +4 (14) HP 27 (5d10) Speed 10 ft. MOD SAVE MOD SAVE MOD SAVE Str 17 +3 +3 Dex 14 +2 +2 Con 10 +0 +0 Int 1 âˆ’5 âˆ’5 Wis 3 âˆ’4 âˆ’4 Cha 1 âˆ’5 âˆ’5 Immunities Poison, Psychic; Charmed, Deafened, Exhaustion, Frightened, Paralyzed, Petrified, Poisoned Senses Blindsight 60 ft.; Passive Perception 6 Languages None CR 2 (XP 450; PB +2) Actions Smother. Melee Attack Roll: +5, reach 5 ft. Hit: 10 (2d6 + 3) Bludgeoning damage. If the target is a Medium or smaller creature, the rug can give it the Grappled con- dition (escape DC 13) instead of dealing damage. Until the grapple ends, the target has the Blinded and Re- strained conditions, is suffocating, and takes 10 (2d6 + 3) Bludgeoning damage at the start of each of its turns. The rug can smother only one creature at a time. While grappling the target, the rug canâ€™t take this ac- tion, the rug halves the damage it takes (round down), and the target takes the same amount of damage.
A7: Ankheg | B7: Ankheg | C7: 2 | D7: Large | E7: Monstrosity | F7: NA | G7: Unaligned | H7: 14 | I7: 0 | J7: 45 (6d10 + 12) | K7: 45 | L7: Speed 30 ft., Burrow 10 ft. | M7: 30 | N7: 17 | O7: 11 | P7: 14 | Q7: 1 | R7: 13 | S7: 6 | T7: 3 | U7: 0 | V7: 2 | W7: -5 | X7: 1 | Y7: -2 | Z7: NA | AA7: NA | AB7: NA | AC7: NA | AD7: NA | AE7: Darkvision 60 ft., Tremorsense 60 ft.; Passive Perception 11 | AF7: None | AG7: Ankheg Large Monstrosity, Unaligned AC 14 Initiative +0 (10) HP 45 (6d10 + 12) Speed 30 ft., Burrow 10 ft. MOD SAVE MOD SAVE MOD SAVE Str 17 +3 +3 Dex 11 +0 +0 Con 14 +2 +2 Int 1 âˆ’5 âˆ’5 Wis 13 +1 +1 Cha 6 âˆ’2 âˆ’2 Senses Darkvision 60 ft., Tremorsense 60 ft.; Passive Perception 11 Languages None CR 2 (XP 450; PB +2) Traits Tunneler. The ankheg can burrow through solid rock at half its Burrow Speed and leaves a 10-foot-diameter tunnel in its wake. Actions Bite. Melee Attack Roll: +5 (with Advantage if the target is Grappled by the ankheg), reach 5 ft. Hit: 10 (2d6 + 3) Slashing damage plus 3 (1d6) Acid damage. If the target is a Large or smaller creature, it has the Grappled con- dition (escape DC 13). Acid Spray (Recharge 6). Dexterity Saving Throw: DC 12, each creature in a 30-foot-long, 5-foot-wide Line. Failure: 14 (4d6) Acid damage. Success: Half damage.
A8: Assassin | B8: Assassin | C8: 8 | D8: Medium or Small | E8: Humanoid | F8: NA | G8: Neutral | H8: 16 | I8: 10 | J8: 97 (15d8 + 30) | K8: 97 | L8: Speed 30 ft. | M8: 30 | N8: 11 | O8: 18 | P8: 14 | Q8: 16 | R8: 11 | S8: 10 | T8: 0 | U8: 7 | V8: 2 | W8: 6 | X8: 0 | Y8: 0 | Z8: Acrobatics +7, Perception +6, Stealth +10 | AA8: Poison | AB8: NA | AC8: NA | AD8: Light Crossbow, Shortsword, Studded Leather Armor | AE8: Passive Perception 16 | AF8: Common, Thievesâ€™ Cant | AG8: Assassin Medium or Small Humanoid, Neutral AC 16 Initiative +10 (20) HP 97 (15d8 + 30) Speed 30 ft. MOD SAVE MOD SAVE MOD SAVE Str 11 +0 +0 Dex 18 +4 +7 Con 14 +2 +2 Int 16 +3 +6 Wis 11 +0 +0 Cha 10 +0 +0 Skills Acrobatics +7, Perception +6, Stealth +10 Resistances Poison Gear Light Crossbow, Shortsword, Studded Leather Armor Senses Passive Perception 16 Languages Common, Thievesâ€™ Cant CR 8 (XP 3,900; PB +3) Traits Evasion. If the assassin is subjected to an effect that allows it to make a Dexterity saving throw to take only half damage, the assassin instead takes no damage if it succeeds on the save and only half damage if it fails. It canâ€™t use this trait if it has the Incapacitated condition. Actions Multiattack. The assassin makes three attacks, using Shortsword or Light Crossbow in any combination. Shortsword. Melee Attack Roll: +7, reach 5 ft. Hit: 7 (1d6 + 4) Piercing damage plus 17 (5d6) Poison dam- age, and the target has the Poisoned condition until the start of the assassinâ€™s next turn. Light Crossbow. Ranged Attack Roll: +7, range 80/320 ft. Hit: 8 (1d8 + 4) Piercing damage plus 21 (6d6) Poison damage. Bonus Actions Cunning Action. The assassin takes the Dash, Disen- gage, or Hide action.
A9: Awakened Shrub | B9: Awakened Plants | C9: 0 | D9: Small | E9: Plant | F9: NA | G9: Neutral | H9: 9 | I9: -1 | J9: 10 (3d6) | K9: 10 | L9: Speed 20 ft. | M9: 20 | N9: 3 | O9: 8 | P9: 11 | Q9: 10 | R9: 10 | S9: 6 | T9: -4 | U9: -1 | V9: 0 | W9: 0 | X9: 0 | Y9: -2 | Z9: NA | AA9: Piercing | AB9: Fire | AC9: NA | AD9: NA | AE9: Passive Perception 10 | AF9: Common plus one other language | AG9: Awakened Shrub Small Plant, Neutral AC 9 Initiative âˆ’1 (9) HP 10 (3d6) Speed 20 ft. MOD SAVE Str 3 âˆ’4 âˆ’4 MOD SAVE Dex 8 âˆ’1 âˆ’1 MOD SAVE Con 11 +0 +0 Int 10 +0 +0 Wis 10 +0 +0 Cha 6 âˆ’2 âˆ’2 Vulnerabilities Fire Resistances Piercing Senses Passive Perception 10 Languages Common plus one other language CR 0 (XP 10; PB +2) Actions Rake. Melee Attack Roll: +1, reach 5 ft. Hit: 1 Slash- ing damage.
A10: Awakened Tree | B10: Awakened Plants | C10: 2 | D10: Huge | E10: Plant | F10: NA | G10: Neutral | H10: 13 | I10: -2 | J10: 59 (7d12 + 14) | K10: 59 | L10: Speed 20 ft. | M10: 20 | N10: 19 | O10: 6 | P10: 15 | Q10: 10 | R10: 10 | S10: 7 | T10: 4 | U10: -2 | V10: 2 | W10: 0 | X10: 0 | Y10: -2 | Z10: NA | AA10: Bludgeoning, Piercing | AB10: Fire | AC10: NA | AD10: NA | AE10: Passive Perception 10 | AF10: Common plus one other language | AG10: Awakened Tree Huge Plant, Neutral AC 13 Initiative âˆ’2 (8) HP 59 (7d12 + 14) Speed 20 ft. MOD SAVE MOD SAVE MOD SAVE Str 19 +4 +4 Dex 6 âˆ’2 âˆ’2 Con 15 +2 +2 Int 10 +0 +0 Wis 10 +0 +0 Cha 7 âˆ’2 âˆ’2 Vulnerabilities Fire Resistances Bludgeoning, Piercing Senses Passive Perception 10 Languages Common plus one other language CR 2 (XP 450; PB +2) Actions Slam. Melee Attack Roll: +6, reach 10 ft. Hit: 14 (3d6 + 4) Bludgeoning damage.
A11: Axe Beak | B11: Axe Beak | C11: 0.25 | D11: Large | E11: Monstrosity | F11: NA | G11: Unaligned | H11: 11 | I11: 1 | J11: 19 (3d10 + 3) | K11: 19 | L11: Speed 50 ft. | M11: 50 | N11: 14 | O11: 12 | P11: 12 | Q11: 2 | R11: 10 | S11: 5 | T11: 2 | U11: 1 | V11: 1 | W11: -4 | X11: 0 | Y11: -3 | Z11: NA | AA11: NA | AB11: NA | AC11: NA | AD11: NA | AE11: Passive Perception 10 | AF11: None | AG11: Axe Beak Large Monstrosity, Unaligned AC 11 Initiative +1 (11) HP 19 (3d10 + 3) Speed 50 ft. MOD SAVE MOD SAVE MOD SAVE Str 14 +2 +2 Dex 12 +1 +1 Con 12 +1 +1 Int 2 âˆ’4 âˆ’4 Wis 10 +0 +0 Cha 5 âˆ’3 âˆ’3 Senses Passive Perception 10 Languages None CR 1/4 (XP 50; PB +2) Actions Beak. Melee Attack Roll: +4, reach 5 ft. Hit: 6 (1d8 + 2) Slashing damage.
A12: Azer Sentinel | B12: Azer | C12: 2 | D12: Medium | E12: Elemental | F12: NA | G12: Lawful Neutral | H12: 17 | I12: 1 | J12: 39 (6d8 + 12) | K12: 39 | L12: Speed 30 ft. | M12: 30 | N12: 17 | O12: 12 | P12: 15 | Q12: 12 | R12: 13 | S12: 10 | T12: 3 | U12: 1 | V12: 4 | W12: 1 | X12: 1 | Y12: 0 | Z12: NA | AA12: NA | AB12: NA | AC12: Fire, Poison; Poisoned | AD12: NA | AE12: Passive Perception 11 | AF12: Primordial (Ignan) | AG12: Azer Sentinel Medium Elemental, Lawful Neutral AC 17 Initiative +1 (11) HP 39 (6d8 + 12) Speed 30 ft. MOD SAVE MOD SAVE MOD SAVE Str 17 +3 +3 Dex 12 +1 +1 Con 15 +2 +4 Int 12 +1 +1 Wis 13 +1 +1 Cha 10 +0 +0 Immunities Fire, Poison; Poisoned Senses Passive Perception 11 Languages Primordial (Ignan) CR 2 (XP 450; PB +2) Traits Fire Aura. At the end of each of the azerâ€™s turns, each creature of the azerâ€™s choice in a 5-foot Emanation orig- inating from the azer takes 5 (1d10) Fire damage unless the azer has the Incapacitated condition. Illumination. The azer sheds Bright Light in a 10-foot radius and Dim Light for an additional 10 feet. Actions Burning Hammer. Melee Attack Roll: +5, reach 5 ft. Hit: 8 (1d10 + 3) Bludgeoning damage plus 3 (1d6) Fire damage.
A13: Balor | B13: Balor | C13: 19 | D13: Huge | E13: Fiend | F13: Demon | G13: Chaotic Evil | H13: 19 | I13: 14 | J13: 287 (23d12 + 138) | K13: 287 | L13: Speed 40 ft., Fly 80 ft. | M13: 40 | N13: 26 | O13: 15 | P13: 22 | Q13: 20 | R13: 16 | S13: 22 | T13: 8 | U13: 2 | V13: 12 | W13: 5 | X13: 9 | Y13: 6 | Z13: Perception +9 | AA13: Cold, Lightning | AB13: NA | AC13: Fire, Poison; Charmed, Frightened, Poisoned | AD13: NA | AE13: Truesight 120 ft.; Passive Perception 19 | AF13: Abyssal; telepathy 120 ft. | AG13: Balor Huge Fiend (Demon), Chaotic Evil AC 19 Initiative +14 (24) HP 287 (23d12 + 138) Speed 40 ft., Fly 80 ft. MOD SAVE MOD SAVE MOD SAVE Str 26 +8 +8 Dex 15 +2 +2 Con 22 +6 +12 Int 20 +5 +5 Wis 16 +3 +9 Cha 22 +6 +6 Skills Perception +9 Resistances Cold, Lightning Immunities Fire, Poison; Charmed, Frightened, Poisoned Senses Truesight 120 ft.; Passive Perception 19 Languages Abyssal; telepathy 120 ft. CR 19 (XP 22,000; PB +6) Traits Death Throes. The balor explodes when it dies. Dex- terity Saving Throw: DC 20, each creature in a 30-foot Emanation originating from the balor. Failure: 31 (9d6) Fire damage plus 31 (9d6) Force damage. Success: Half damage. Failure or Success: If the balor dies outside the Abyss, it gains a new body instantly, reviving with all its Hit Points somewhere in the Abyss. Fire Aura. At the end of each of the balorâ€™s turns, each creature in a 5-foot Emanation originating from the ba- lor takes 13 (3d8) Fire damage. Legendary Resistance (3/Day). If the balor fails a saving throw, it can choose to succeed instead. Magic Resistance. The balor has Advantage on saving throws against spells and other magical effects. Actions Multiattack. The balor makes one Flame Whip attack and one Lightning Blade attack. Flame Whip. Melee Attack Roll: +14, reach 30 ft. Hit: 18 (3d6 + 8) Force damage plus 17 (5d6) Fire damage. If the target is a Huge or smaller creature, the balor pulls the target up to 25 feet straight toward itself, and the target has the Prone condition. Lightning Blade. Melee Attack Roll: +14, reach 10 ft. Hit: 21 (3d8 + 8) Force damage plus 22 (4d10) Light- ning damage, and the target canâ€™t take Reactions until the start of the balorâ€™s next turn. Bonus Actions Teleport. The balor teleports itself or a willing demon within 10 feet of itself up to 60 feet to an unoccupied space the balor can see.
... A331: Wolf | B331: Animals | C331: 0.25 | D331: Medium | E331: Beast | F331: NA | G331: Unaligned | H331: 12 | I331: 2 | J331: 11 (2d8 + 2) | K331: 11 | L331: Speed 40 ft. | M331: 40 | N331: 14 | O331: 15 | P331: 12 | Q331: 3 | R331: 12 | S331: 6 | T331: 2 | U331: 2 | V331: 1 | W331: -4 | X331: 1 | Y331: -2 | Z331: Perception +5, Stealth +4 | AA331: NA | AB331: NA | AC331: NA | AD331: NA | AE331: Darkvision 60 ft.; Passive Perception 15 | AF331: None | AG331: Wolf Medium Beast, Unaligned AC 12 Initiative +2 (12) HP 11 (2d8 + 2) Speed 40 ft. MOD SAVE MOD SAVE MOD SAVE Str 14 +2 +2 Dex 15 +2 +2 Con 12 +1 +1 Int 3 âˆ’4 âˆ’4 Wis 12 +1 +1 Cha 6 âˆ’2 âˆ’2 Skills Perception +5, Stealth +4 Senses Darkvision 60 ft.; Passive Perception 15 Languages None CR 1/4 (XP 50; PB +2) Traits Pack Tactics. The wolf has Advantage on attack rolls against a creature if at least one of the wolfâ€™s allies is within 5 feet of the creature and the ally doesnâ€™t have the Incapacitated condition. Actions Bite. Melee Attack Roll: +4, reach 5 ft. Hit: 5 (1d6 + 2) Piercing damage. If the target is a Medium or smaller creature, it has the Prone condition.

Sheet monsters
A1: name | B1: category | C1: cr | D1: size | E1: type | F1: descriptive_tags | G1: alignment | H1: ac | I1: initiative | J1: hp | K1: hp_number | L1: speed | M1: speed_base_number | N1: str | O1: dex | P1: con | Q1: int | R1: wis | S1: cha | T1: str_save | U1: dex_save | V1: con_save | W1: int_save | X1: wis_save | Y1: cha_save | Z1: skills | AA1: resistances | AB1: vulnerabilities | AC1: immunities | AD1: gear | AE1: senses | AF1: languages | AG1: full_text
A2: Aboleth | B2: Aboleth | C2: 10 | D2: Large | E2: Aberration | F2: NA | G2: Lawful Evil | H2: 17 | I2: 7 | J2: 150 (20d10 + 40) | K2: 150 | L2: Speed 10 ft., Swim 40 ft. | M2: 10 | N2: 21 | O2: 9 | P2: 15 | Q2: 18 | R2: 15 | S2: 18 | T2: 5 | U2: 3 | V2: 6 | W2: 8 | X2: 6 | Y2: 4 | Z2: History +12, Perception +10 | AA2: NA | AB2: NA | AC2: NA | AD2: NA | AE2: Darkvision 120 ft.; Passive Perception 20 | AF2: Deep Speech; telepathy 120 ft. | AG2: Aboleth Large Aberration, Lawful Evil AC 17 Initiative +7 (17) HP 150 (20d10 + 40) Speed 10 ft., Swim 40 ft. MOD SAVE MOD SAVE MOD SAVE Str 21 +5 +5 Dex 9 âˆ’1 +3 Con 15 +2 +6 Int 18 +4 +8 Wis 15 +2 +6 Cha 18 +4 +4 Skills History +12, Perception +10 Senses Darkvision 120 ft.; Passive Perception 20 Languages Deep Speech; telepathy 120 ft. CR 10 (XP 5,900, or 7,200 in lair; PB +4) Traits Amphibious. The aboleth can breathe air and water. Eldritch Restoration. If destroyed, the aboleth gains a new body in 5d10 days, reviving with all its Hit Points in the Far Realm or another location chosen by the GM. Legendary Resistance (3/Day, or 4/Day in Lair). If the aboleth fails a saving throw, it can choose to suc- ceed instead. Mucus Cloud. While underwater, the aboleth is sur- rounded by mucus. Constitution Saving Throw: DC 14, each creature in a 5-foot Emanation originating from the aboleth at the end of the aboleth's turn. Failure: The target is cursed. Until the curse ends, the target's skin becomes slimy, the target can breathe air and water, and it can't regain Hit Points unless it is underwater. While the cursed creature is outside a body of water, the creature takes 6 (1d12) Acid damage at the end of every 10 minutes unless moisture is applied to its skin before those minutes have passed. Probing Telepathy. If a creature the aboleth can see communicates telepathically with the aboleth, the abo- leth learns the creature's greatest desires. Actions Multiattack. The aboleth makes two Tentacle attacks and uses either Consume Memories or Dominate Mind if available. Tentacle. Melee Attack Roll: +9, reach 15 ft. Hit: 12 (2d6 + 5) Bludgeoning damage. If the target is a Large or smaller creature, it has the Grappled condition (es- cape DC 14) from one of four tentacles. Consume Memories. Intelligence Saving Throw: DC 16, one creature within 30 feet that is Charmed or Grap- pled by the aboleth. Failure: 10 (3d6) Psychic damage. Success: Half damage. Failure or Success: The aboleth gains the target's memories if the target is a Humanoid and is reduced to 0 Hit Points by this action. Dominate Mind (2/Day). Wisdom Saving Throw: DC 16, one creature the aboleth can see within 30 feet. Failure: The target has the Charmed condition until the aboleth dies or is on a different plane of existence from the target. While Charmed, the target acts as an ally to the aboleth and is under its control while within 60 feet of it. In addition, the aboleth and the target can communicate telepathically with each other over any distance. The target repeats the save whenever it takes damage as well as after every 24 hours it spends at least 1 mile away from the aboleth, ending the effect on itself on a success. Legendary Actions Legendary Action Uses: 3 (4 in Lair). Immediately after another creature's turn, the aboleth can expend a use to take one of the following actions. The aboleth regains all expended uses at the start of each of its turns. Lash. The aboleth makes one Tentacle attack. Psychic Drain. If the aboleth has at least one creature Charmed or Grappled, it uses Consume Memories and regains 5 (1d10) Hit Points.
A3: Air Elemental | B3: Air Elemental | C3: 5 | D3: Large | E3: Elemental | F3: NA | G3: Neutral | H3: 15 | I3: 5 | J3: 90 (12d10 + 24) | K3: 90 | L3: Speed 10 ft., Fly 90 ft. (hover) | M3: 10 | N3: 14 | O3: 20 | P3: 14 | Q3: 6 | R3: 10 | S3: 6 | T3: 2 | U3: 5 | V3: 2 | W3: -2 | X3: 0 | Y3: -2 | Z3: NA | AA3: Bludgeoning, Lightning, Piercing, Slashing | AB3: NA | AC3: Poison, Thunder; Exhaustion, Grappled, Paralyzed, Petrified, Poisoned, Prone, Restrained, Unconscious | AD3: NA | AE3: Darkvision 60 ft.; Passive Perception 10 | AF3: Primordial (Auran) | AG3: Air Elemental Large Elemental, Neutral AC 15 Initiative +5 (15) HP 90 (12d10 + 24) Speed 10 ft., Fly 90 ft. (hover) MOD SAVE MOD SAVE MOD SAVE Str 14 +2 +2 Dex 20 +5 +5 Con 14 +2 +2 Int 6 âˆ’2 âˆ’2 Wis 10 +0 +0 Cha 6 âˆ’2 âˆ’2 Resistances Bludgeoning, Lightning, Piercing, Slashing Immunities Poison, Thunder; Exhaustion, Grappled, Paralyzed, Petrified, Poisoned, Prone, Restrained, Unconscious Senses Darkvision 60 ft.; Passive Perception 10 Languages Primordial (Auran) CR 5 (XP 1,800; PB +3) Traits Air Form. The elemental can enter a creature's space and stop there. It can move through a space as narrow as 1 inch without expending extra movement to do so. Actions Multiattack. The elemental makes two Thunderous Slam attacks. Thunderous Slam. Melee Attack Roll: +8, reach 10 ft. Hit: 14 (2d8 + 5) Thunder damage. Whirlwind (Recharge 4â€“6). Strength Saving Throw: DC 13, one Medium or smaller creature in the elemental's space. Failure: 24 (4d10 + 2) Thunder damage, and the target is pushed up to 20 feet straight away from the elemental and has the Prone condition. Success: Half damage only.
A4: Animated Armor | B4: Animated Objects | C4: 1 | D4: Medium | E4: Construct | F4: NA | G4: Unaligned | H4: 18 | I4: 2 | J4: 33 (6d8 + 6) | K4: 33 | L4: Speed 25 ft. | M4: 25 | N4: 14 | O4: 11 | P4: 13 | Q4: 1 | R4: 3 | S4: 1 | T4: 2 | U4: 0 | V4: 1 | W4: -5 | X4: -4 | Y4: -5 | Z4: NA | AA4: NA | AB4: NA | AC4: Poison, Psychic; Charmed, Deafened, Exhaustion, Frightened, Paralyzed, Petrified, Poisoned | AD4: NA | AE4: Blindsight 60 ft.; Passive Perception 6 | AF4: None | AG4: Animated Armor Medium Construct, Unaligned AC 18 Initiative +2 (12) HP 33 (6d8 + 6) Speed 25 ft. MOD SAVE MOD SAVE MOD SAVE Str 14 +2 +2 Dex 11 +0 +0 Con 13 +1 +1 Int 1 âˆ’5 âˆ’5 Wis 3 âˆ’4 âˆ’4 Cha 1 âˆ’5 âˆ’5 Immunities Poison, Psychic; Charmed, Deafened, Exhaustion, Frightened, Paralyzed, Petrified, Poisoned Senses Blindsight 60 ft.; Passive Perception 6 Languages None CR 1 (XP 200; PB +2) Actions Multiattack. The armor makes two Slam attacks. Slam. Melee Attack Roll: +4, reach 5 ft. Hit: 5 (1d6 + 2) Bludgeoning damage.
A5: Animated Flying Sword | B5: Animated Objects | C5: 0.25 | D5: Small | E5: Construct | F5: NA | G5: Unaligned | H5: 17 | I5: 4 | J5: 14 (4d6) | K5: 14 | L5: Speed 5 ft., Fly 50 ft. (hover) | M5: 5 | N5: 12 | O5: 15 | P5: 11 | Q5: 1 | R5: 5 | S5: 1 | T5: 1 | U5: 4 | V5: 0 | W5: -5 | X5: -3 | Y5: -5 | Z5: NA | AA5: NA | AB5: NA | AC5: Poison, Psychic; Charmed, Deafened, Exhaustion, Frightened, Paralyzed, Petrified, Poisoned | AD5: NA | AE5: Blindsight 60 ft.; Passive Perception 7 | AF5: None | AG5: Animated Flying Sword Small Construct, Unaligned AC 17 Initiative +4 (14) HP 14 (4d6) Speed 5 ft., Fly 50 ft. (hover) MOD SAVE MOD SAVE MOD SAVE Str 12 +1 +1 Dex 15 +2 +4 Con 11 +0 +0 Int 1 âˆ’5 âˆ’5 Wis 5 âˆ’3 âˆ’3 Cha 1 âˆ’5 âˆ’5 Immunities Poison, Psychic; Charmed, Deafened, Exhaustion, Frightened, Paralyzed, Petrified, Poisoned Senses Blindsight 60 ft.; Passive Perception 7 Languages None CR 1/4 (XP 50; PB +2) Actions Slash. Melee Attack Roll: +4, reach 5 ft. Hit: 6 (1d8 + 2) Slashing damage.
A6: Animated Rug of Smothering | B6: Animated Objects | C6: 2 | D6: Large | E6: Construct | F6: NA | G6: Unaligned | H6: 12 | I6: 4 | J6: 27 (5d10) | K6: 27 | L6: Speed 10 ft. | M6: 10 | N6: 17 | O6: 14 | P6: 10 | Q6: 1 | R6: 3 | S6: 1 | T6: 3 | U6: 2 | V6: 0 | W6: -5 | X6: -4 | Y6: -5 | Z6: NA | AA6: NA | AB6: NA | AC6: Poison, Psychic; Charmed, Deafened, Exhaustion, Frightened, Paralyzed, Petrified, Poisoned | AD6: NA | AE6: Blindsight 60 ft.; Passive Perception 6 | AF6: None | AG6: Animated Rug of Smothering Large Construct, Unaligned AC 12 Initiative +4 (14) HP 27 (5d10) Speed 10 ft. MOD SAVE MOD SAVE MOD SAVE Str 17 +3 +3 Dex 14 +2 +2 Con 10 +0 +0 Int 1 âˆ’5 âˆ’5 Wis 3 âˆ’4 âˆ’4 Cha 1 âˆ’5 âˆ’5 Immunities Poison, Psychic; Charmed, Deafened, Exhaustion, Frightened, Paralyzed, Petrified, Poisoned Senses Blindsight 60 ft.; Passive Perception 6 Languages None CR 2 (XP 450; PB +2) Actions Smother. Melee Attack Roll: +5, reach 5 ft. Hit: 10 (2d6 + 3) Bludgeoning damage. If the target is a Medium or smaller creature, the rug can give it the Grappled con- dition (escape DC 13) instead of dealing damage. Until the grapple ends, the target has the Blinded and Re- strained conditions, is suffocating, and takes 10 (2d6 + 3) Bludgeoning damage at the start of each of its turns. The rug can smother only one creature at a time. While grappling the target, the rug can't take this ac- tion, the rug halves the damage it takes (round down), and the target takes the same amount of damage.
A7: Ankheg | B7: Ankheg | C7: 2 | D7: Large | E7: Monstrosity | F7: NA | G7: Unaligned | H7: 14 | I7: 0 | J7: 45 (6d10 + 12) | K7: 45 | L7: Speed 30 ft., Burrow 10 ft. | M7: 30 | N7: 17 | O7: 11 | P7: 14 | Q7: 1 | R7: 13 | S7: 6 | T7: 3 | U7: 0 | V7: 2 | W7: -5 | X7: 1 | Y7: -2 | Z7: NA | AA7: NA | AB7: NA | AC7: NA | AD7: NA | AE7: Darkvision 60 ft., Tremorsense 60 ft.; Passive Perception 11 | AF7: None | AG7: Ankheg Large Monstrosity, Unaligned AC 14 Initiative +0 (10) HP 45 (6d10 + 12) Speed 30 ft., Burrow 10 ft. MOD SAVE MOD SAVE MOD SAVE Str 17 +3 +3 Dex 11 +0 +0 Con 14 +2 +2 Int 1 âˆ’5 âˆ’5 Wis 13 +1 +1 Cha 6 âˆ’2 âˆ’2 Senses Darkvision 60 ft., Tremorsense 60 ft.; Passive Perception 11 Languages None CR 2 (XP 450; PB +2) Traits Tunneler. The ankheg can burrow through solid rock at half its Burrow Speed and leaves a 10-foot-diameter tunnel in its wake. Actions Bite. Melee Attack Roll: +5 (with Advantage if the target is Grappled by the ankheg), reach 5 ft. Hit: 10 (2d6 + 3) Slashing damage plus 3 (1d6) Acid damage. If the target is a Large or smaller creature, it has the Grappled con- dition (escape DC 13). Acid Spray (Recharge 6). Dexterity Saving Throw: DC 12, each creature in a 30-foot-long, 5-foot-wide Line. Failure: 14 (4d6) Acid damage. Success: Half damage.
A8: Assassin | B8: Assassin | C8: 8 | D8: Medium or Small | E8: Humanoid | F8: NA | G8: Neutral | H8: 16 | I8: 10 | J8: 97 (15d8 + 30) | K8: 97 | L8: Speed 30 ft. | M8: 30 | N8: 11 | O8: 18 | P8: 14 | Q8: 16 | R8: 11 | S8: 10 | T8: 0 | U8: 7 | V8: 2 | W8: 6 | X8: 0 | Y8: 0 | Z8: Acrobatics +7, Perception +6, Stealth +10 | AA8: Poison | AB8: NA | AC8: NA | AD8: Light Crossbow, Shortsword, Studded Leather Armor | AE8: Passive Perception 16 | AF8: Common, Thieves' Cant | AG8: Assassin Medium or Small Humanoid, Neutral AC 16 Initiative +10 (20) HP 97 (15d8 + 30) Speed 30 ft. MOD SAVE MOD SAVE MOD SAVE Str 11 +0 +0 Dex 18 +4 +7 Con 14 +2 +2 Int 16 +3 +6 Wis 11 +0 +0 Cha 10 +0 +0 Skills Acrobatics +7, Perception +6, Stealth +10 Resistances Poison Gear Light Crossbow, Shortsword, Studded Leather Armor Senses Passive Perception 16 Languages Common, Thieves' Cant CR 8 (XP 3,900; PB +3) Traits Evasion. If the assassin is subjected to an effect that allows it to make a Dexterity saving throw to take only half damage, the assassin instead takes no damage if it succeeds on the save and only half damage if it fails. It can't use this trait if it has the Incapacitated condition. Actions Multiattack. The assassin makes three attacks, using Shortsword or Light Crossbow in any combination. Shortsword. Melee Attack Roll: +7, reach 5 ft. Hit: 7 (1d6 + 4) Piercing damage plus 17 (5d6) Poison dam- age, and the target has the Poisoned condition until the start of the assassin's next turn. Light Crossbow. Ranged Attack Roll: +7, range 80/320 ft. Hit: 8 (1d8 + 4) Piercing damage plus 21 (6d6) Poison damage. Bonus Actions Cunning Action. The assassin takes the Dash, Disen- gage, or Hide action.
A9: Awakened Shrub | B9: Awakened Plants | C9: 0 | D9: Small | E9: Plant | F9: NA | G9: Neutral | H9: 9 | I9: -1 | J9: 10 (3d6) | K9: 10 | L9: Speed 20 ft. | M9: 20 | N9: 3 | O9: 8 | P9: 11 | Q9: 10 | R9: 10 | S9: 6 | T9: -4 | U9: -1 | V9: 0 | W9: 0 | X9: 0 | Y9: -2 | Z9: NA | AA9: Piercing | AB9: Fire | AC9: NA | AD9: NA | AE9: Passive Perception 10 | AF9: Common plus one other language | AG9: Awakened Shrub Small Plant, Neutral AC 9 Initiative âˆ’1 (9) HP 10 (3d6) Speed 20 ft. MOD SAVE Str 3 âˆ’4 âˆ’4 MOD SAVE Dex 8 âˆ’1 âˆ’1 MOD SAVE Con 11 +0 +0 Int 10 +0 +0 Wis 10 +0 +0 Cha 6 âˆ’2 âˆ’2 Vulnerabilities Fire Resistances Piercing Senses Passive Perception 10 Languages Common plus one other language CR 0 (XP 10; PB +2) Actions Rake. Melee Attack Roll: +1, reach 5 ft. Hit: 1 Slash- ing damage.
A10: Awakened Tree | B10: Awakened Plants | C10: 2 | D10: Huge | E10: Plant | F10: NA | G10: Neutral | H10: 13 | I10: -2 | J10: 59 (7d12 + 14) | K10: 59 | L10: Speed 20 ft. | M10: 20 | N10: 19 | O10: 6 | P10: 15 | Q10: 10 | R10: 10 | S10: 7 | T10: 4 | U10: -2 | V10: 2 | W10: 0 | X10: 0 | Y10: -2 | Z10: NA | AA10: Bludgeoning, Piercing | AB10: Fire | AC10: NA | AD10: NA | AE10: Passive Perception 10 | AF10: Common plus one other language | AG10: Awakened Tree Huge Plant, Neutral AC 13 Initiative âˆ’2 (8) HP 59 (7d12 + 14) Speed 20 ft. MOD SAVE MOD SAVE MOD SAVE Str 19 +4 +4 Dex 6 âˆ’2 âˆ’2 Con 15 +2 +2 Int 10 +0 +0 Wis 10 +0 +0 Cha 7 âˆ’2 âˆ’2 Vulnerabilities Fire Resistances Bludgeoning, Piercing Senses Passive Perception 10 Languages Common plus one other language CR 2 (XP 450; PB +2) Actions Slam. Melee Attack Roll: +6, reach 10 ft. Hit: 14 (3d6 + 4) Bludgeoning damage.
A11: Axe Beak | B11: Axe Beak | C11: 0.25 | D11: Large | E11: Monstrosity | F11: NA | G11: Unaligned | H11: 11 | I11: 1 | J11: 19 (3d10 + 3) | K11: 19 | L11: Speed 50 ft. | M11: 50 | N11: 14 | O11: 12 | P11: 12 | Q11: 2 | R11: 10 | S11: 5 | T11: 2 | U11: 1 | V11: 1 | W11: -4 | X11: 0 | Y11: -3 | Z11: NA | AA11: NA | AB11: NA | AC11: NA | AD11: NA | AE11: Passive Perception 10 | AF11: None | AG11: Axe Beak Large Monstrosity, Unaligned AC 11 Initiative +1 (11) HP 19 (3d10 + 3) Speed 50 ft. MOD SAVE MOD SAVE MOD SAVE Str 14 +2 +2 Dex 12 +1 +1 Con 12 +1 +1 Int 2 âˆ’4 âˆ’4 Wis 10 +0 +0 Cha 5 âˆ’3 âˆ’3 Senses Passive Perception 10 Languages None CR 1/4 (XP 50; PB +2) Actions Beak. Melee Attack Roll: +4, reach 5 ft. Hit: 6 (1d8 + 2) Slashing damage.
A12: Azer Sentinel | B12: Azer | C12: 2 | D12: Medium | E12: Elemental | F12: NA | G12: Lawful Neutral | H12: 17 | I12: 1 | J12: 39 (6d8 + 12) | K12: 39 | L12: Speed 30 ft. | M12: 30 | N12: 17 | O12: 12 | P12: 15 | Q12: 12 | R12: 13 | S12: 10 | T12: 3 | U12: 1 | V12: 4 | W12: 1 | X12: 1 | Y12: 0 | Z12: NA | AA12: NA | AB12: NA | AC12: Fire, Poison; Poisoned | AD12: NA | AE12: Passive Perception 11 | AF12: Primordial (Ignan) | AG12: Azer Sentinel Medium Elemental, Lawful Neutral AC 17 Initiative +1 (11) HP 39 (6d8 + 12) Speed 30 ft. MOD SAVE MOD SAVE MOD SAVE Str 17 +3 +3 Dex 12 +1 +1 Con 15 +2 +4 Int 12 +1 +1 Wis 13 +1 +1 Cha 10 +0 +0 Immunities Fire, Poison; Poisoned Senses Passive Perception 11 Languages Primordial (Ignan) CR 2 (XP 450; PB +2) Traits Fire Aura. At the end of each of the azer's turns, each creature of the azer's choice in a 5-foot Emanation orig- inating from the azer takes 5 (1d10) Fire damage unless the azer has the Incapacitated condition. Illumination. The azer sheds Bright Light in a 10-foot radius and Dim Light for an additional 10 feet. Actions Burning Hammer. Melee Attack Roll: +5, reach 5 ft. Hit: 8 (1d10 + 3) Bludgeoning damage plus 3 (1d6) Fire damage.
A13: Balor | B13: Balor | C13: 19 | D13: Huge | E13: Fiend | F13: Demon | G13: Chaotic Evil | H13: 19 | I13: 14 | J13: 287 (23d12 + 138) | K13: 287 | L13: Speed 40 ft., Fly 80 ft. | M13: 40 | N13: 26 | O13: 15 | P13: 22 | Q13: 20 | R13: 16 | S13: 22 | T13: 8 | U13: 2 | V13: 12 | W13: 5 | X13: 9 | Y13: 6 | Z13: Perception +9 | AA13: Cold, Lightning | AB13: NA | AC13: Fire, Poison; Charmed, Frightened, Poisoned | AD13: NA | AE13: Truesight 120 ft.; Passive Perception 19 | AF13: Abyssal; telepathy 120 ft. | AG13: Balor Huge Fiend (Demon), Chaotic Evil AC 19 Initiative +14 (24) HP 287 (23d12 + 138) Speed 40 ft., Fly 80 ft. MOD SAVE MOD SAVE MOD SAVE Str 26 +8 +8 Dex 15 +2 +2 Con 22 +6 +12 Int 20 +5 +5 Wis 16 +3 +9 Cha 22 +6 +6 Skills Perception +9 Resistances Cold, Lightning Immunities Fire, Poison; Charmed, Frightened, Poisoned Senses Truesight 120 ft.; Passive Perception 19 Languages Abyssal; telepathy 120 ft. CR 19 (XP 22,000; PB +6) Traits Death Throes. The balor explodes when it dies. Dex- terity Saving Throw: DC 20, each creature in a 30-foot Emanation originating from the balor. Failure: 31 (9d6) Fire damage plus 31 (9d6) Force damage. Success: Half damage. Failure or Success: If the balor dies outside the Abyss, it gains a new body instantly, reviving with all its Hit Points somewhere in the Abyss. Fire Aura. At the end of each of the balor's turns, each creature in a 5-foot Emanation originating from the ba- lor takes 13 (3d8) Fire damage. Legendary Resistance (3/Day). If the balor fails a saving throw, it can choose to succeed instead. Magic Resistance. The balor has Advantage on saving throws against spells and other magical effects. Actions Multiattack. The balor makes one Flame Whip attack and one Lightning Blade attack. Flame Whip. Melee Attack Roll: +14, reach 30 ft. Hit: 18 (3d6 + 8) Force damage plus 17 (5d6) Fire damage. If the target is a Huge or smaller creature, the balor pulls the target up to 25 feet straight toward itself, and the target has the Prone condition. Lightning Blade. Melee Attack Roll: +14, reach 10 ft. Hit: 21 (3d8 + 8) Force damage plus 22 (4d10) Light- ning damage, and the target can't take Reactions until the start of the balor's next turn. Bonus Actions Teleport. The balor teleports itself or a willing demon within 10 feet of itself up to 60 feet to an unoccupied space the balor can see.
... A331: Wolf | B331: Animals | C331: 0.25 | D331: Medium | E331: Beast | F331: NA | G331: Unaligned | H331: 12 | I331: 2 | J331: 11 (2d8 + 2) | K331: 11 | L331: Speed 40 ft. | M331: 40 | N331: 14 | O331: 15 | P331: 12 | Q331: 3 | R331: 12 | S331: 6 | T331: 2 | U331: 2 | V331: 1 | W331: -4 | X331: 1 | Y331: -2 | Z331: Perception +5, Stealth +4 | AA331: NA | AB331: NA | AC331: NA | AD331: NA | AE331: Darkvision 60 ft.; Passive Perception 15 | AF331: None | AG331: Wolf Medium Beast, Unaligned AC 12 Initiative +2 (12) HP 11 (2d8 + 2) Speed 40 ft. MOD SAVE MOD SAVE MOD SAVE Str 14 +2 +2 Dex 15 +2 +2 Con 12 +1 +1 Int 3 âˆ’4 âˆ’4 Wis 12 +1 +1 Cha 6 âˆ’2 âˆ’2 Skills Perception +5, Stealth +4 Senses Darkvision 60 ft.; Passive Perception 15 Languages None CR 1/4 (XP 50; PB +2) Traits Pack Tactics. The wolf has Advantage on attack rolls against a creature if at least one of the wolf's allies is within 5 feet of the creature and the ally doesn't have the Incapacitated condition. Actions Bite. Melee Attack Roll: +4, reach 5 ft. Hit: 5 (1d6 + 2) Piercing damage. If the target is a Medium or smaller creature, it has the Prone condition.

Sheet StrByType
A1: Types | B1: Elemental | C1: Monstrosity | D1: Humanoid | E1: Fiend | F1: Dragon | G1: Fey | H1: Undead | I1: Beast | J1: Other | Y1: Highest: | Z1: Monstrosity, Dragon | AA1: (Kraken), (Tarrasque)
B2: {=_xlfn._xlws.FILTER(monsters!$N$2:$N$331,monsters!$E$2:$E$331=StrByType!B1,"")} -> 14 | C2: {=_xlfn._xlws.FILTER(monsters!$N$2:$N$331,monsters!$E$2:$E$331=StrByType!C1,"")} -> 17 | D2: {=_xlfn._xlws.FILTER(monsters!$N$2:$N$331,monsters!$E$2:$E$331=StrByType!D1,"")} -> 11 | E2: {=_xlfn._xlws.FILTER(monsters!$N$2:$N$331,monsters!$E$2:$E$331=StrByType!E1,"")} -> 26 | F2: {=_xlfn._xlws.FILTER(monsters!$N$2:$N$331,monsters!$E$2:$E$331=StrByType!F1,"")} -> 15 | G2: {=_xlfn._xlws.FILTER(monsters!$N$2:$N$331,monsters!$E$2:$E$331=StrByType!G1,"")} -> 12 | H2: {=_xlfn._xlws.FILTER(monsters!$N$2:$N$331,monsters!$E$2:$E$331=StrByType!H1,"")} -> 16 | I2: {=_xlfn._xlws.FILTER(monsters!$N$2:$N$331,monsters!$E$2:$E$331=StrByType!I1,"")} -> 19 | J2: {=_xlfn._xlws.FILTER(monsters!$N$2:$N$331,(monsters!E2:E331<>StrByType!B1)*(monsters!E2:E331<>StrByType!C1)*(monsters!E2:E331<>StrByType!D1)*(monsters!E2:E331<>StrByType!E1)*(monsters!E2:E331<>StrByType!F1)*(monsters!E2:E331<>StrByType!G1)*(monsters!E2:E331<>StrByType!H1)*(monsters!E2:E331<>StrByType!I1),"")} -> 21 | Y2: Lowest: | Z2: Undead, Beast, Other | AA2: (Will-o'-Wisp, Specter), (Frog, Seahorse), (Shrieker Fungus)
B3: 17 | C3: 14 | D3: 11 | E3: 16 | F3: 19 | G3: 17 | H3: 7 | I3: 19 | J3: 14
B4: 21 | C4: 16 | D4: 15 | E4: 16 | F4: 23 | G4: 15 | H4: 13 | I4: 16 | J4: 12
B5: 20 | C5: 23 | D5: 16 | E5: 18 | F5: 27 | G5: 18 | H5: 11 | I5: 18 | J5: 17
B6: 22 | C6: 19 | D6: 10 | E6: 18 | F6: 17 | G6: 10 | H6: 16 | I6: 8 | J6: 3
B7: 10 | C7: 19 | D7: 11 | E7: 12 | F7: 21 | G7: 8 | H7: 18 | I7: 10 | J7: 19
B8: 15 | C8: 6 | D8: 11 | E8: 18 | F8: 25 | G8: 8 | H8: 6 | I8: 2 | J8: 16
B9: 16 | C9: 15 | D9: 10 | E9: 20 | F9: 29 | G9: 10 | H9: 10 | I9: 15 | J9: 19
B10: 7 | C10: 11 | D10: 18 | E10: 14 | F10: 15 | G10: 18 | H10: 18 | I10: 6 | J10: 20
B11: 5 | C11: 16 | D11: 13 | E11: 17 | F11: 19 | G11: 13 | H11: 18 | I11: 13 | J11: 17
B12: 7 | C12: 14 | D12: 18 | E12: 19 | F12: 23 | G12: 15 | H12: 1 | I12: 17 | J12: 27
B13: 8 | C13: 18 | D13: 16 | E13: 22 | F13: 27 | G13: 12 | H13: 16 | I13: 15 | J13: 16
B14: 5 | C14: 12 | D14: 9 | E14: 21 | F14: 17 | G14: 16 | H14: 18 | I14: 3 | J14: 14
... B16: 18 | C16: 20 | D16: 11 | E16: 8 | F16: 25 | G16: 16 | H16: 1 | I16: 6 | J16: 18
B17: 18 | C17: 30 | D17: 10 | E17: 16 | F17: 29 | H17: 6 | I17: 15 | J17: 21
B18: 17 | C18: 17 | D18: 10 | E18: 10 | F18: 15 | H18: 13 | I18: 11 | J18: 25
C19: 10 | D19: 14 | E19: 18 | F19: 19 | H19: 19 | I19: 17 | J19: 19
C20: 18 | D20: 16 | E20: 21 | F20: 23 | I20: 18 | J20: 23
C21: 17 | D21: 11 | E21: 18 | F21: 27 | I21: 6 | J21: 1
C22: 18 | D22: 10 | E22: 18 | F22: 25 | I22: 22 | J22: 3
C23: 20 | D23: 15 | E23: 19 | F23: 19 | I23: 16 | J23: 14
C24: 15 | D24: 17 | E24: 26 | F24: 23 | I24: 1 | J24: 10
C25: 28 | D25: 17 | E25: 5 | F25: 27 | I25: 23 | J25: 20
C26: 24 | D26: 13 | E26: 14 | F26: 30 | I26: 13 | J26: 12
C27: 28 | D27: 16 | E27: 13 | F27: 15 | I27: 15 | J27: 14
C28: 13 | E28: 18 | F28: 19 | I28: 17 | J28: 16
C29: 4 | E29: 8 | F29: 23 | I29: 5 | J29: 19
C30: 30 | E30: 17 | F30: 27 | I30: 19 | J30: 21
C31: 19 | F31: 19 | I31: 13 | J31: 4
C32: 17 | F32: 7 | I32: 21 | J32: 24
C33: 10 | F33: 6 | I33: 8 | J33: 15
C34: 17 | F34: 19 | I34: 12 | J34: 19
C35: 16 | F35: 23 | I35: 17 | J35: 16
C36: 18 | F36: 27 | I36: 16 | J36: 18
C37: 4 | F37: 30 | I37: 15 | J37: 24
C38: 15 | F38: 19 | I38: 17 | J38: 18
F39: 23 | I39: 7 | J39: 18
F40: 27 | I40: 16 | J40: 18
F41: 30 | I41: 15 | J41: 26
...

Sheet DexByType
A1: Types | B1: Elemental | C1: Monstrosity | D1: Humanoid | E1: Fiend | F1: Dragon | G1: Fey | H1: Undead | I1: Beast | J1: Other | Y1: Highest: | Z1: Undead | AA1: (Will-o'-Wisp)
B2: {=_xlfn._xlws.FILTER(monsters!$O$2:$O$331,monsters!$E$2:$E$331=DexByType!B1,"")} -> 20 | C2: {=_xlfn._xlws.FILTER(monsters!$O$2:$O$331,monsters!$E$2:$E$331=DexByType!C1,"")} -> 11 | D2: {=_xlfn._xlws.FILTER(monsters!$O$2:$O$331,monsters!$E$2:$E$331=DexByType!D1,"")} -> 18 | E2: {=_xlfn._xlws.FILTER(monsters!$O$2:$O$331,monsters!$E$2:$E$331=DexByType!E1,"")} -> 15 | F2: {=_xlfn._xlws.FILTER(monsters!$O$2:$O$331,monsters!$E$2:$E$331=DexByType!F1,"")} -> 14 | G2: {=_xlfn._xlws.FILTER(monsters!$O$2:$O$331,monsters!$E$2:$E$331=DexByType!G1,"")} -> 17 | H2: {=_xlfn._xlws.FILTER(monsters!$O$2:$O$331,monsters!$E$2:$E$331=DexByType!H1,"")} -> 17 | I2: {=_xlfn._xlws.FILTER(monsters!$O$2:$O$331,monsters!$E$2:$E$331=DexByType!I1,"")} -> 13 | J2: {=_xlfn._xlws.FILTER(monsters!$O$2:$O$331,(monsters!E2:E331<>DexByType!B1)*(monsters!E2:E331<>DexByType!C1)*(monsters!E2:E331<>DexByType!D1)*(monsters!E2:E331<>DexByType!E1)*(monsters!E2:E331<>DexByType!F1)*(monsters!E2:E331<>DexByType!G1)*(monsters!E2:E331<>DexByType!H1)*(monsters!E2:E331<>DexByType!I1),"")} -> 9 | Y2: Lowest: | Z2: Other | AA2: (Shrieker Fungus, Violent Fungus)
B3: 12 | C3: 12 | D3: 12 | E3: 17 | F3: 14 | G3: 14 | H3: 13 | I3: 11 | J3: 11
B4: 15 | C4: 8 | D4: 16 | E4: 15 | F4: 14 | G4: 14 | H4: 15 | I4: 14 | J4: 15
B5: 8 | C5: 16 | D5: 12 | E5: 16 | F5: 14 | G5: 14 | H5: 16 | I5: 16 | J5: 14
B6: 12 | C6: 11 | D6: 10 | E6: 15 | F6: 10 | G6: 12 | H6: 8 | I6: 14 | J6: 8
B7: 17 | C7: 11 | D7: 12 | E7: 11 | F7: 10 | G7: 15 | H7: 10 | I7: 11 | J7: 6
B8: 11 | C8: 12 | D8: 14 | E8: 16 | F8: 10 | G8: 15 | H8: 14 | I8: 15 | J8: 5
B9: 19 | C9: 14 | D9: 12 | E9: 15 | F9: 10 | G9: 15 | H9: 16 | I9: 12 | J9: 10
B10: 15 | C10: 18 | D10: 15 | E10: 12 | F10: 10 | G10: 12 | H10: 12 | I10: 14 | J10: 9
B11: 14 | C11: 19 | D11: 12 | E11: 12 | F11: 10 | G11: 12 | H11: 11 | I11: 11 | J11: 15
B12: 13 | C12: 15 | D12: 14 | E12: 17 | F12: 10 | G12: 14 | H12: 14 | I12: 12 | J12: 10
B13: 12 | C13: 15 | D13: 11 | E13: 17 | F13: 10 | G13: 16 | H13: 16 | I13: 8 | J13: 20
B14: 11 | C14: 13 | D14: 14 | E14: 14 | F14: 10 | G14: 13 | H14: 18 | I14: 15 | J14: 14
... B16: 14 | C16: 12 | D16: 12 | E16: 17 | F16: 10 | G16: 13 | H16: 28 | I16: 11 | J16: 18
B17: 14 | C17: 11 | D17: 16 | E17: 13 | F17: 10 | H17: 16 | I17: 10 | J17: 8
B18: 10 | C18: 16 | D18: 18 | E18: 5 | F18: 12 | H18: 6 | I18: 16 | J18: 9
C19: 17 | D19: 10 | E19: 20 | F19: 12 | H19: 6 | I19: 15 | J19: 9
C20: 15 | D20: 10 | E20: 10 | F20: 12 | I20: 10 | J20: 9
C21: 12 | D21: 14 | E21: 15 | F21: 12 | I21: 15 | J21: 1
C22: 11 | D22: 15 | E22: 15 | F22: 10 | I22: 9 | J22: 1
C23: 12 | D23: 12 | E23: 11 | F23: 14 | I23: 10 | J23: 3
C24: 16 | D24: 14 | E24: 14 | F24: 14 | I24: 13 | J24: 8
C25: 7 | D25: 16 | E25: 17 | F25: 14 | I25: 14 | J25: 11
C26: 13 | D26: 11 | E26: 17 | F26: 14 | I26: 10 | J26: 6
C27: 10 | D27: 13 | E27: 11 | F27: 12 | I27: 16 | J27: 14
C28: 12 | E28: 17 | F28: 12 | I28: 10 | J28: 12
C29: 16 | E29: 17 | F29: 12 | I29: 14 | J29: 18
C30: 11 | E30: 15 | F30: 12 | I30: 14 | J30: 8
C31: 10 | F31: 14 | I31: 13 | J31: 15
C32: 10 | F32: 15 | I32: 9 | J32: 9
C33: 16 | F33: 15 | I33: 10 | J33: 6
C34: 15 | F34: 10 | I34: 13 | J34: 8
C35: 14 | F35: 10 | I35: 13 | J35: 11
C36: 13 | F36: 10 | I36: 14 | J36: 15
C37: 15 | F37: 10 | I37: 12 | J37: 20
C38: 10 | F38: 10 | I38: 13 | J38: 8
F39: 10 | I39: 16 | J39: 8
F40: 10 | I40: 13 | J40: 8
F41: 10 | I41: 12 | J41: 22
...

Sheet ConByType
A1: Types | B1: Elemental | C1: Monstrosity | D1: Humanoid | E1: Fiend | F1: Dragon | G1: Fey | H1: Undead | I1: Beast | J1: Other | Y1: Highest: | Z1: Monstrosity | AA1: (Tarrasque)
B2: {=_xlfn._xlws.FILTER(monsters!$P$2:$P$331,monsters!$E$2:$E$331=DexByType!B1,"")} -> 14 | C2: {=_xlfn._xlws.FILTER(monsters!$P$2:$P$331,monsters!$E$2:$E$331=DexByType!C1,"")} -> 14 | D2: {=_xlfn._xlws.FILTER(monsters!$P$2:$P$331,monsters!$E$2:$E$331=DexByType!D1,"")} -> 14 | E2: {=_xlfn._xlws.FILTER(monsters!$P$2:$P$331,monsters!$E$2:$E$331=DexByType!E1,"")} -> 22 | F2: {=_xlfn._xlws.FILTER(monsters!$P$2:$P$331,monsters!$E$2:$E$331=DexByType!F1,"")} -> 13 | G2: {=_xlfn._xlws.FILTER(monsters!$P$2:$P$331,monsters!$E$2:$E$331=DexByType!G1,"")} -> 12 | H2: {=_xlfn._xlws.FILTER(monsters!$P$2:$P$331,monsters!$E$2:$E$331=DexByType!H1,"")} -> 10 | I2: {=_xlfn._xlws.FILTER(monsters!$P$2:$P$331,monsters!$E$2:$E$331=DexByType!I1,"")} -> 17 | J2: {=_xlfn._xlws.FILTER(monsters!$P$2:$P$331,(monsters!E2:E331<>DexByType!B1)*(monsters!E2:E331<>DexByType!C1)*(monsters!E2:E331<>DexByType!D1)*(monsters!E2:E331<>DexByType!E1)*(monsters!E2:E331<>DexByType!F1)*(monsters!E2:E331<>DexByType!G1)*(monsters!E2:E331<>DexByType!H1)*(monsters!E2:E331<>DexByType!I1),"")} -> 15 | Y2: Lowest: | Z2: Beast | AA2: (Bat, Frog, Hawk, Owl, Scorpion, Seahorse, Spider, Weasel)
B3: 15 | C3: 12 | D3: 12 | E3: 18 | F3: 17 | G3: 14 | H3: 10 | I3: 15 | J3: 13
B4: 22 | C4: 15 | D4: 14 | E4: 15 | F4: 21 | G4: 13 | H4: 10 | I4: 14 | J4: 11
B5: 20 | C5: 18 | D5: 17 | E5: 18 | F5: 25 | G5: 14 | H5: 16 | I5: 13 | J5: 10
B6: 24 | C6: 21 | D6: 10 | E6: 18 | F6: 15 | G6: 11 | H6: 15 | I6: 11 | J6: 11
B7: 16 | C7: 19 | D7: 10 | E7: 12 | F7: 19 | G7: 10 | H7: 17 | I7: 16 | J7: 15
B8: 16 | C8: 12 | D8: 12 | E8: 18 | F8: 23 | G8: 10 | H8: 13 | I8: 8 | J8: 16
B9: 14 | C9: 14 | D9: 13 | E9: 21 | F9: 27 | G9: 10 | H9: 15 | I9: 14 | J9: 16
B10: 12 | C10: 14 | D10: 16 | E10: 11 | F10: 13 | G10: 16 | H10: 15 | I10: 10 | J10: 18
B11: 10 | C11: 18 | D11: 12 | E11: 14 | F11: 17 | G11: 12 | H11: 15 | I11: 14 | J11: 12
B12: 10 | C12: 13 | D12: 16 | E12: 20 | F12: 21 | G12: 14 | H12: 11 | I12: 15 | J12: 22
B13: 12 | C13: 16 | D13: 14 | E13: 21 | F13: 25 | G13: 11 | H13: 16 | I13: 17 | J13: 17
B14: 10 | C14: 12 | D14: 11 | E14: 18 | F14: 15 | G14: 16 | H14: 18 | I14: 10 | J14: 11
... B16: 15 | C16: 20 | D16: 11 | E16: 13 | F16: 23 | G16: 13 | H16: 10 | I16: 12 | J16: 18
B17: 18 | C17: 26 | D17: 12 | E17: 15 | F17: 27 | H17: 16 | I17: 13 | J17: 17
B18: 22 | C18: 17 | D18: 14 | E18: 11 | F18: 13 | H18: 16 | I18: 11 | J18: 23
C19: 16 | D19: 12 | E19: 20 | F19: 17 | H19: 18 | I19: 15 | J19: 18
C20: 15 | D20: 12 | E20: 22 | F20: 21 | I20: 15 | J20: 21
C21: 15 | D21: 12 | E21: 16 | F21: 25 | I21: 12 | J21: 10
C22: 16 | D22: 10 | E22: 16 | F22: 20 | I22: 17 | J22: 10
C23: 17 | D23: 14 | E23: 16 | F23: 17 | I23: 11 | J23: 20
C24: 12 | D24: 16 | E24: 24 | F24: 21 | I24: 8 | J24: 16
C25: 22 | D25: 15 | E25: 10 | F25: 25 | I25: 18 | J25: 18
C26: 21 | D26: 11 | E26: 18 | F26: 29 | I26: 17 | J26: 16
C27: 20 | D27: 14 | E27: 12 | F27: 13 | I27: 11 | J27: 11
C28: 13 | E28: 14 | F28: 17 | I28: 16 | J28: 12
C29: 11 | E29: 13 | F29: 21 | I29: 12 | J29: 16
C30: 30 | E30: 18 | F30: 25 | I30: 12 | J30: 19
C31: 17 | F31: 16 | I31: 11 | J31: 14
C32: 15 | F32: 9 | I32: 17 | J32: 20
C33: 12 | F33: 13 | I33: 12 | J33: 14
C34: 16 | F34: 17 | I34: 11 | J34: 16
C35: 14 | F35: 21 | I35: 12 | J35: 19
C36: 14 | F36: 25 | I36: 14 | J36: 16
C37: 11 | F37: 29 | I37: 13 | J37: 24
C38: 16 | F38: 17 | I38: 13 | J38: 17
F39: 21 | I39: 11 | J39: 16
F40: 25 | I40: 15 | J40: 18
F41: 29 | I41: 11 | J41: 26
...

Sheet IntByType
A1: Types | B1: Elemental | C1: Monstrosity | D1: Humanoid | E1: Fiend | F1: Dragon | G1: Fey | H1: Undead | I1: Beast | J1: Other | Y1: Highest: | Z1: Other | AA1: (Solar)
B2: {=_xlfn._xlws.FILTER(monsters!$Q$2:$Q$331,monsters!$E$2:$E$331=DexByType!B1,"")} -> 6 | C2: {=_xlfn._xlws.FILTER(monsters!$Q$2:$Q$331,monsters!$E$2:$E$331=DexByType!C1,"")} -> 1 | D2: {=_xlfn._xlws.FILTER(monsters!$Q$2:$Q$331,monsters!$E$2:$E$331=DexByType!D1,"")} -> 16 | E2: {=_xlfn._xlws.FILTER(monsters!$Q$2:$Q$331,monsters!$E$2:$E$331=DexByType!E1,"")} -> 20 | F2: {=_xlfn._xlws.FILTER(monsters!$Q$2:$Q$331,monsters!$E$2:$E$331=DexByType!F1,"")} -> 10 | G2: {=_xlfn._xlws.FILTER(monsters!$Q$2:$Q$331,monsters!$E$2:$E$331=DexByType!G1,"")} -> 10 | H2: {=_xlfn._xlws.FILTER(monsters!$Q$2:$Q$331,monsters!$E$2:$E$331=DexByType!H1,"")} -> 11 | I2: {=_xlfn._xlws.FILTER(monsters!$Q$2:$Q$331,monsters!$E$2:$E$331=DexByType!I1,"")} -> 2 | J2: {=_xlfn._xlws.FILTER(monsters!$Q$2:$Q$331,(monsters!E2:E331<>DexByType!B1)*(monsters!E2:E331<>DexByType!C1)*(monsters!E2:E331<>DexByType!D1)*(monsters!E2:E331<>DexByType!E1)*(monsters!E2:E331<>DexByType!F1)*(monsters!E2:E331<>DexByType!G1)*(monsters!E2:E331<>DexByType!H1)*(monsters!E2:E331<>DexByType!I1),"")} -> 18 | Y2: Lowest: | Z2: Monstrosity, Fiend, Beast, Other | AA2: (33 monsters)
B3: 12 | C3: 2 | D3: 10 | E3: 12 | F3: 12 | G3: 11 | H3: 10 | I3: 2 | J3: 1
B4: 15 | C4: 2 | D4: 14 | E4: 9 | F4: 14 | G4: 8 | H4: 7 | I4: 6 | J4: 1
B5: 5 | C5: 7 | D5: 9 | E5: 13 | F5: 16 | G5: 9 | H5: 21 | I5: 4 | J5: 1
B6: 16 | C6: 2 | D6: 10 | E6: 11 | F6: 12 | G6: 14 | H6: 6 | I6: 4 | J6: 10
B7: 6 | C7: 3 | D7: 10 | E7: 5 | F7: 14 | G7: 10 | H7: 11 | I7: 2 | J7: 10
B8: 6 | C8: 2 | D8: 10 | E8: 14 | F8: 16 | G8: 10 | H8: 6 | I8: 2 | J8: 1
B9: 10 | C9: 3 | D9: 12 | E9: 19 | F9: 18 | G9: 10 | H9: 6 | I9: 2 | J9: 5
B10: 8 | C10: 11 | D10: 10 | E10: 6 | F10: 10 | G10: 13 | H10: 2 | I10: 3 | J10: 3
B11: 9 | C11: 13 | D11: 10 | E11: 6 | F11: 12 | G11: 10 | H11: 6 | I11: 2 | J11: 13
B12: 9 | C12: 7 | D12: 12 | E12: 5 | F12: 14 | G12: 12 | H12: 10 | I12: 2 | J12: 12
B13: 7 | C13: 2 | D13: 11 | E13: 12 | F13: 16 | G13: 12 | H13: 11 | I13: 2 | J13: 18
B14: 11 | C14: 7 | D14: 17 | E14: 18 | F14: 12 | G14: 12 | H14: 17 | I14: 3 | J14: 5
... B16: 11 | C16: 2 | D16: 12 | E16: 15 | F16: 16 | G16: 7 | H16: 13 | I16: 1 | J16: 17
B17: 5 | C17: 22 | D17: 8 | E17: 14 | F17: 18 | H17: 12 | I17: 2 | J17: 6
B18: 11 | C18: 7 | D18: 10 | E18: 1 | F18: 14 | H18: 3 | I18: 2 | J18: 10
C19: 12 | D19: 10 | E19: 18 | F19: 16 | H19: 3 | I19: 3 | J19: 6
C20: 8 | D20: 13 | E20: 19 | F20: 18 | I20: 2 | J20: 9
C21: 5 | D21: 11 | E21: 16 | F21: 20 | I21: 2 | J21: 1
C22: 6 | D22: 12 | E22: 10 | F22: 10 | I22: 3 | J22: 1
C23: 3 | D23: 10 | E23: 14 | F23: 14 | I23: 2 | J23: 1
C24: 6 | D24: 11 | E24: 22 | F24: 16 | I24: 1 | J24: 3
C25: 1 | D25: 10 | E25: 7 | F25: 16 | I25: 5 | J25: 2
C26: 4 | D26: 8 | E26: 13 | F26: 18 | I26: 2 | J26: 1
C27: 3 | D27: 10 | E27: 12 | F27: 14 | I27: 2 | J27: 3
C28: 2 | E28: 16 | F28: 16 | I28: 2 | J28: 9
C29: 2 | E29: 15 | F29: 18 | I29: 1 | J29: 16
C30: 3 | E30: 8 | F30: 20 | I30: 1 | J30: 5
C31: 11 | F31: 10 | I31: 1 | J31: 10
C32: 10 | F32: 8 | I32: 2 | J32: 3
C33: 11 | F33: 10 | I33: 1 | J33: 2
C34: 10 | F34: 12 | I34: 2 | J34: 5
C35: 10 | F35: 14 | I35: 3 | J35: 6
C36: 7 | F36: 16 | I36: 2 | J36: 10
C37: 2 | F37: 18 | I37: 2 | J37: 19
C38: 6 | F38: 12 | I38: 5 | J38: 7
F39: 14 | I39: 2 | J39: 5
F40: 16 | I40: 1 | J40: 7
F41: 18 | I41: 2 | J41: 25
...

Sheet WisByType
A1: Types | B1: Elemental | C1: Monstrosity | D1: Humanoid | E1: Fiend | F1: Dragon | G1: Fey | H1: Undead | I1: Beast | J1: Other | Y1: Highest: | Z1: Other | AA1: (Solar)
B2: {=_xlfn._xlws.FILTER(monsters!$R$2:$R$331,monsters!$E$2:$E$331=DexByType!B1,"")} -> 10 | C2: {=_xlfn._xlws.FILTER(monsters!$R$2:$R$331,monsters!$E$2:$E$331=DexByType!C1,"")} -> 13 | D2: {=_xlfn._xlws.FILTER(monsters!$R$2:$R$331,monsters!$E$2:$E$331=DexByType!D1,"")} -> 11 | E2: {=_xlfn._xlws.FILTER(monsters!$R$2:$R$331,monsters!$E$2:$E$331=DexByType!E1,"")} -> 16 | F2: {=_xlfn._xlws.FILTER(monsters!$R$2:$R$331,monsters!$E$2:$E$331=DexByType!F1,"")} -> 11 | G2: {=_xlfn._xlws.FILTER(monsters!$R$2:$R$331,monsters!$E$2:$E$331=DexByType!G1,"")} -> 13 | H2: {=_xlfn._xlws.FILTER(monsters!$R$2:$R$331,monsters!$E$2:$E$331=DexByType!H1,"")} -> 10 | I2: {=_xlfn._xlws.FILTER(monsters!$R$2:$R$331,monsters!$E$2:$E$331=DexByType!I1,"")} -> 12 | J2: {=_xlfn._xlws.FILTER(monsters!$R$2:$R$331,(monsters!E2:E331<>DexByType!B1)*(monsters!E2:E331<>DexByType!C1)*(monsters!E2:E331<>DexByType!D1)*(monsters!E2:E331<>DexByType!E1)*(monsters!E2:E331<>DexByType!F1)*(monsters!E2:E331<>DexByType!G1)*(monsters!E2:E331<>DexByType!H1)*(monsters!E2:E331<>DexByType!I1),"")} -> 15 | Y2: Lowest: | Z2: Other | AA2: (Animated Armor, Animated Rug of Smothering, Shrieking Fungus, Violent Fungus)
B3: 13 | C3: 10 | D3: 10 | E3: 14 | F3: 11 | G3: 12 | H3: 12 | I3: 12 | J3: 3
B4: 16 | C4: 8 | D4: 11 | E4: 11 | F4: 13 | G4: 11 | H4: 10 | I4: 12 | J4: 5
B5: 10 | C5: 14 | D5: 11 | E5: 14 | F5: 15 | G5: 13 | H5: 14 | I5: 14 | J5: 3
B6: 15 | C6: 10 | D6: 10 | E6: 12 | F6: 11 | G6: 15 | H6: 12 | I6: 12 | J6: 10
B7: 10 | C7: 14 | D7: 11 | E7: 8 | F7: 13 | G7: 8 | H7: 19 | I7: 12 | J7: 10
B8: 11 | C8: 13 | D8: 14 | E8: 14 | F8: 15 | G8: 8 | H8: 10 | I8: 12 | J8: 6
B9: 15 | C9: 13 | D9: 16 | E9: 17 | F9: 17 | G9: 8 | H9: 8 | I9: 12 | J9: 11
B10: 11 | C10: 12 | D10: 12 | E10: 10 | F10: 11 | G10: 14 | H10: 8 | I10: 14 | J10: 8
B11: 11 | C11: 16 | D11: 11 | E11: 13 | F11: 11 | G11: 10 | H11: 8 | I11: 9 | J11: 14
B12: 11 | C12: 12 | D12: 14 | E12: 12 | F12: 13 | G12: 10 | H12: 10 | I12: 13 | J12: 16
B13: 10 | C13: 13 | D13: 11 | E13: 16 | F13: 15 | G13: 10 | H13: 10 | I13: 11 | J13: 20
B14: 10 | C14: 10 | D14: 12 | E14: 15 | F14: 11 | G14: 12 | H14: 15 | I14: 12 | J14: 10
... B16: 10 | C16: 10 | D16: 14 | E16: 12 | F16: 15 | G16: 11 | H16: 14 | I16: 8 | J16: 20
B17: 10 | C17: 18 | D17: 12 | E17: 15 | F17: 17 | H17: 14 | I17: 10 | J17: 10
B18: 10 | C18: 12 | D18: 14 | E18: 11 | F18: 11 | H18: 6 | I18: 14 | J18: 14
C19: 13 | D19: 14 | E19: 16 | F19: 13 | H19: 6 | I19: 12 | J19: 10
C20: 10 | D20: 16 | E20: 12 | F20: 15 | I20: 11 | J20: 10
C21: 13 | D21: 13 | E21: 14 | F21: 17 | I21: 14 | J21: 3
C22: 16 | D22: 14 | E22: 13 | F22: 12 | I22: 11 | J22: 3
C23: 12 | D23: 10 | E23: 12 | F23: 11 | I23: 10 | J23: 6
C24: 10 | D24: 10 | E24: 18 | F24: 13 | I24: 8 | J24: 10
C25: 8 | D25: 10 | E25: 10 | F25: 15 | I25: 12 | J25: 12
C26: 10 | D26: 11 | E26: 16 | F26: 17 | I26: 12 | J26: 6
C27: 10 | D27: 11 | E27: 13 | F27: 11 | I27: 12 | J27: 14
C28: 13 | E28: 15 | F28: 13 | I28: 7 | J28: 8
C29: 8 | E29: 12 | F29: 15 | I29: 7 | J29: 19
C30: 11 | E30: 13 | F30: 17 | I30: 10 | J30: 9
C31: 12 | F31: 15 | I31: 9 | J31: 10
C32: 11 | F32: 7 | I32: 10 | J32: 11
C33: 10 | F33: 12 | I33: 7 | J33: 6
C34: 13 | F34: 11 | I34: 10 | J34: 7
C35: 11 | F35: 11 | I35: 12 | J35: 13
C36: 12 | F36: 13 | I36: 12 | J36: 15
C37: 12 | F37: 15 | I37: 10 | J37: 22
C38: 12 | F38: 11 | I38: 10 | J38: 16
F39: 11 | I39: 10 | J39: 10
F40: 13 | I40: 9 | J40: 10
F41: 15 | I41: 12 | J41: 25
...

Sheet ChaByType
A1: Types | B1: Elemental | C1: Monstrosity | D1: Humanoid | E1: Fiend | F1: Dragon | G1: Fey | H1: Undead | I1: Beast | J1: Other | Y1: Highest: | Z1: Other | AA1: (Solar)
B2: {=_xlfn._xlws.FILTER(monsters!$S$2:$S$331,monsters!$E$2:$E$331=DexByType!B1,"")} -> 6 | C2: {=_xlfn._xlws.FILTER(monsters!$S$2:$S$331,monsters!$E$2:$E$331=DexByType!C1,"")} -> 6 | D2: {=_xlfn._xlws.FILTER(monsters!$S$2:$S$331,monsters!$E$2:$E$331=DexByType!D1,"")} -> 10 | E2: {=_xlfn._xlws.FILTER(monsters!$S$2:$S$331,monsters!$E$2:$E$331=DexByType!E1,"")} -> 22 | F2: {=_xlfn._xlws.FILTER(monsters!$S$2:$S$331,monsters!$E$2:$E$331=DexByType!F1,"")} -> 13 | G2: {=_xlfn._xlws.FILTER(monsters!$S$2:$S$331,monsters!$E$2:$E$331=DexByType!G1,"")} -> 11 | H2: {=_xlfn._xlws.FILTER(monsters!$S$2:$S$331,monsters!$E$2:$E$331=DexByType!H1,"")} -> 8 | I2: {=_xlfn._xlws.FILTER(monsters!$S$2:$S$331,monsters!$E$2:$E$331=DexByType!I1,"")} -> 5 | J2: {=_xlfn._xlws.FILTER(monsters!$S$2:$S$331,(monsters!E2:E331<>DexByType!B1)*(monsters!E2:E331<>DexByType!C1)*(monsters!E2:E331<>DexByType!D1)*(monsters!E2:E331<>DexByType!E1)*(monsters!E2:E331<>DexByType!F1)*(monsters!E2:E331<>DexByType!G1)*(monsters!E2:E331<>DexByType!H1)*(monsters!E2:E331<>DexByType!I1),"")} -> 18 | Y2: Lowest: | Z2: Other | AA2: (13 monsters)
B3: 10 | C3: 5 | D3: 10 | E3: 14 | F3: 15 | G3: 11 | H3: 17 | I3: 5 | J3: 1
B4: 20 | C4: 7 | D4: 14 | E4: 14 | F4: 19 | G4: 9 | H4: 6 | I4: 7 | J4: 1
B5: 5 | C5: 12 | D5: 9 | E5: 16 | F5: 22 | G5: 11 | H5: 16 | I5: 6 | J5: 1
B6: 19 | C6: 5 | D6: 10 | E6: 14 | F6: 15 | G6: 18 | H6: 12 | I6: 6 | J6: 6
B7: 7 | C7: 10 | D7: 10 | E7: 3 | F7: 17 | G7: 8 | H7: 16 | I7: 5 | J7: 7
B8: 7 | C8: 5 | D8: 13 | E8: 18 | F8: 20 | G8: 8 | H8: 8 | I8: 4 | J8: 1
B9: 11 | C9: 6 | D9: 11 | E9: 16 | F9: 25 | G9: 10 | H9: 5 | I9: 7 | J9: 5
B10: 10 | C10: 14 | D10: 15 | E10: 7 | F10: 13 | G10: 14 | H10: 5 | I10: 5 | J10: 1
B11: 10 | C11: 12 | D11: 10 | E11: 6 | F11: 15 | G11: 9 | H11: 5 | I11: 5 | J11: 7
B12: 12 | C12: 8 | D12: 13 | E12: 13 | F12: 17 | G12: 13 | H12: 11 | I12: 7 | J12: 16
B13: 10 | C13: 8 | D13: 15 | E13: 18 | F13: 22 | G13: 14 | H13: 12 | I13: 5 | J13: 18
B14: 12 | C14: 13 | D14: 11 | E14: 18 | F14: 15 | G14: 13 | H14: 18 | I14: 7 | J14: 4
... B16: 12 | C16: 7 | D16: 16 | E16: 20 | F16: 20 | G16: 8 | H16: 11 | I16: 2 | J16: 20
B17: 8 | C17: 20 | D17: 14 | E17: 16 | F17: 25 | H17: 15 | I17: 5 | J17: 8
B18: 11 | C18: 8 | D18: 17 | E18: 3 | F18: 13 | H18: 5 | I18: 5 | J18: 13
C19: 15 | D19: 11 | E19: 20 | F19: 15 | H19: 5 | I19: 7 | J19: 5
C20: 9 | D20: 13 | E20: 15 | F20: 18 | I20: 7 | J20: 12
C21: 8 | D21: 11 | E21: 16 | F21: 22 | I21: 7 | J21: 1
C22: 9 | D22: 16 | E22: 15 | F22: 12 | I22: 6 | J22: 1
C23: 7 | D23: 11 | E23: 15 | F23: 16 | I23: 6 | J23: 1
C24: 6 | D24: 11 | E24: 24 | F24: 20 | I24: 3 | J24: 6
C25: 4 | D25: 14 | E25: 10 | F25: 24 | I25: 7 | J25: 7
C26: 5 | D26: 8 | E26: 20 | F26: 28 | I26: 5 | J26: 2
C27: 9 | D27: 10 | E27: 9 | F27: 13 | I27: 6 | J27: 5
C28: 6 | E28: 16 | F28: 15 | I28: 5 | J28: 6
